Workbook
Name Fenestration: Lists!$A$5:$A$11
Name Res: Lists!$A$1:$A$2
Name SURFACE2: 'Raw Data'!$Q$3:$Q$24
Name re: Lists!$R$65
Name BSA: 'Lighting Zones'!$D$2:$D$6
Name Doors: Lists!$A$49:$A$50
Name Path: '4. Compliance'!$B$4
Name rf: Lists!$R$66
Name Roof_Type: Lists!$A$31:$A$33
Name Res: Lists!$A$1:$A$2
Name cfm: 'HVAC Air-side'!$C$18
Name Ltg_Space: 'Lighting Lookup'!$E$2:$E$108
Name bhp: 'HVAC Air-side'!$C$26
Name Yes_No: Lists!$N$1:$N$2
Name YESNO: 'Lighting Zones'!$B$11:$B$12
Name SxSCategories: 'Lighting Lookup'!$E$2:$E$112
Name Modeled_Square_Feet: '1,2,3 Information'!$C$32
Name Slab: Lists!$A$46:$A$47
Name rd: Lists!$R$64
Name Ltg_ctrl: 'Lighting Lookup'!$I$2:$I$6
Name Type: Lists!$A$1:$A$2
Name BAMCategories: 'Lighting Lookup'!$A$2:$A$33
Name fan_eff: 'HVAC Air-side'!$C$27
Name Floor: Lists!$A$42:$A$44
Name Ltg_Bldg: 'Lighting Lookup'!$A$2:$A$33
Name rb: Lists!$R$62
Name Res: Lists!$A$1:$A$2
Name LZ: 'Lighting Zones'!$B$2:$B$6
Name LZDEC: 'Lighting Zones'!$C$2:$C$6
Name LZONE: 'Lighting Zones'!$A$2:$A$6
Name Wall_Type: Lists!$A$35:$A$38
Name ra: Lists!$R$61
Name rca: Lists!$R$63
Name Env_Type: Lists!$A$1:$A$3
Name Res: Lists!$A$1:$A$2
Name HVAC: Lists!$A$54:$A$77

Sheet Color legend
A4: WORKBOOK COLOR LEGEND
A5: Do not edit: information
A6: Do not edit: formulas
A7: Do not edit: error
A8: User edit: required information
A9: User edit: drop-down menu
A10: User edit: drop-down menu (only for use with Appendix G)
A11: User edit: formula + drop-down menu
A12: User edit: fill in box

Sheet Schedules - Assembly
A1: Hour of Day (Time) | B1: Schedule for Occupancy | E1: Schedule for Lighting/Receptacle | H1: Schedule for HVAC System | K1: Schedule for Service Hot Water | N1: Schedule for Elevator
B2: Percent of Maximum Load | E2: Percent of Maximum Load | K2: Percent of Maximum Load | N2: Percent of Maximum Load
B3: Wk | C3: Sat | D3: Sun | E3: Wk | F3: Sat | G3: Sun | H3: Wk | I3: Sat | J3: Sun | K3: Wk | L3: Sat | M3: Sun | N3: Wk | O3: Sat | P3: Sun
A4: 1 (12-1am) | B4: 0 | C4: 0 | D4: 0 | E4: 5 | F4: 5 | G4: 5 | H4: Off | I4: Off | J4: Off | K4: 0 | L4: 0 | M4: 0 | N4: 0 | O4: 0 | P4: 0
A5: 2 (1-2am) | B5: 0 | C5: 0 | D5: 0 | E5: 5 | F5: 5 | G5: 5 | H5: Off | I5: Off | J5: Off | K5: 0 | L5: 0 | M5: 0 | N5: 0 | O5: 0 | P5: 0
A6: 3 (2-3am) | B6: 0 | C6: 0 | D6: 0 | E6: 5 | F6: 5 | G6: 5 | H6: Off | I6: Off | J6: Off | K6: 0 | L6: 0 | M6: 0 | N6: 0 | O6: 0 | P6: 0
A7: 4 (3-4am) | B7: 0 | C7: 0 | D7: 0 | E7: 5 | F7: 5 | G7: 5 | H7: Off | I7: Off | J7: Off | K7: 0 | L7: 0 | M7: 0 | N7: 0 | O7: 0 | P7: 0
A8: 5 (4-5am) | B8: 0 | C8: 0 | D8: 0 | E8: 5 | F8: 5 | G8: 5 | H8: Off | I8: Off | J8: Off | K8: 0 | L8: 0 | M8: 0 | N8: 0 | O8: 0 | P8: 0
A9: 6 (5-6am) | B9: 0 | C9: 0 | D9: 0 | E9: 5 | F9: 5 | G9: 5 | H9: On | I9: Off | J9: Off | K9: 0 | L9: 0 | M9: 0 | N9: 0 | O9: 0 | P9: 0
A10: 7 (6-7am) | B10: 0 | C10: 0 | D10: 0 | E10: 35/40 | F10: 5 | G10: 5 | H10: On | I10: On | J10: On | K10: 0 | L10: 0 | M10: 0 | N10: 0 | O10: 0 | P10: 0
A11: 8 (7-8am) | B11: 0 | C11: 0 | D11: 0 | E11: 35/40 | F11: 30 | G11: 30 | H11: On | I11: On | J11: On | K11: 0 | L11: 0 | M11: 0 | N11: 0 | O11: 0 | P11: 0
A12: 9 (8-9am) | B12: 20 | C12: 20 | D12: 10 | E12: 35/40 | F12: 30 | G12: 30 | H12: On | I12: On | J12: On | K12: 0 | L12: 0 | M12: 0 | N12: 0 | O12: 0 | P12: 0
A13: 10 (9-10am) | B13: 20 | C13: 20 | D13: 10 | E13: 65/75 | F13: 40/50 | G13: 30 | H13: On | I13: On | J13: On | K13: 5 | L13: 5 | M13: 5 | N13: 0 | O13: 0 | P13: 0
A14: 11 (10-11am) | B14: 20 | C14: 20 | D14: 10 | E14: 65/75 | F14: 40/50 | G14: 30 | H14: On | I14: On | J14: On | K14: 5 | L14: 5 | M14: 5 | N14: 0 | O14: 0 | P14: 0
A15: 12 (11-12pm) | B15: 80 | C15: 60 | D15: 10 | E15: 65/75 | F15: 40/50 | G15: 30 | H15: On | I15: On | J15: On | K15: 35 | L15: 20 | M15: 10 | N15: 0 | O15: 0 | P15: 0
A16: 13 (12-1pm) | B16: 80 | C16: 60 | D16: 10 | E16: 65/75 | F16: 40/50 | G16: 55/65 | H16: On | I16: On | J16: On | K16: 5 | L16: 0 | M16: 0 | N16: 0 | O16: 0 | P16: 0
A17: 14 (1-2pm) | B17: 80 | C17: 60 | D17: 70 | E17: 65/75 | F17: 40/50 | G17: 55/65 | H17: On | I17: On | J17: On | K17: 5 | L17: 0 | M17: 0 | N17: 0 | O17: 0 | P17: 0
A18: 15 (2-3pm) | B18: 80 | C18: 60 | D18: 70 | E18: 65/75 | F18: 40/50 | G18: 55/65 | H18: On | I18: On | J18: On | K18: 5 | L18: 0 | M18: 0 | N18: 0 | O18: 0 | P18: 0
A19: 16 (3-4pm) | B19: 80 | C19: 60 | D19: 70 | E19: 65/75 | F19: 40/50 | G19: 55/65 | H19: On | I19: On | J19: On | K19: 5 | L19: 0 | M19: 0 | N19: 0 | O19: 0 | P19: 0
A20: 17 (4-5pm) | B20: 80 | C20: 60 | D20: 70 | E20: 65/75 | F20: 40/50 | G20: 55/65 | H20: On | I20: On | J20: On | K20: 5 | L20: 0 | M20: 0 | N20: 0 | O20: 0 | P20: 0
A21: 18 (5-6pm) | B21: 80 | C21: 60 | D21: 70 | E21: 65/75 | F21: 40/50 | G21: 55/65 | H21: On | I21: On | J21: On | K21: 0 | L21: 0 | M21: 0 | N21: 0 | O21: 0 | P21: 0
A22: 19 (6-7pm) | B22: 20 | C22: 60 | D22: 70 | E22: 65/75 | F22: 40/50 | G22: 55/65 | H22: On | I22: On | J22: On | K22: 0 | L22: 0 | M22: 0 | N22: 0 | O22: 0 | P22: 0
A23: 20 (7-8pm) | B23: 20 | C23: 60 | D23: 70 | E23: 65/75 | F23: 40/50 | G23: 55/65 | H23: On | I23: On | J23: On | K23: 0 | L23: 65 | M23: 65 | N23: 0 | O23: 0 | P23: 0
A24: 21 (8-9pm) | B24: 20 | C24: 60 | D24: 70 | E24: 65/75 | F24: 40/50 | G24: 55/65 | H24: On | I24: On | J24: On | K24: 0 | L24: 30 | M24: 30 | N24: 0 | O24: 0 | P24: 0
A25: 22 (9-10pm) | B25: 20 | C25: 80 | D25: 70 | E25: 65/75 | F25: 40/50 | G25: 55/65 | H25: On | I25: On | J25: On | K25: 0 | L25: 0 | M25: 0 | N25: 0 | O25: 0 | P25: 0
A26: 23 (10-11pm) | B26: 10 | C26: 10 | D26: 20 | E26: 25 | F26: 40/50 | G26: 55/65 | H26: On | I26: On | J26: On | K26: 0 | L26: 0 | M26: 0 | N26: 0 | O26: 0 | P26: 0
A27: 24 (11-12am) | B27: 0 | C27: 0 | D27: 0 | E27: 5 | F27: 5 | G27: 5 | H27: Off | I27: Off | J27: Off | K27: 0 | L27: 0 | M27: 0 | N27: 0 | O27: 0 | P27: 0
A28: Total/Day | B28: =SUM(B4:B27) -> 710 | C28: =SUM(C4:C27) -> 750 | D28: =SUM(D4:D27) -> 700 | E28: 1010/1155 | F28: 660/800 | G28: 745/845 | H28: 1800 | I28: 1700 | J28: 1700 | K28: =SUM(K4:K27) -> 70 | L28: =SUM(L4:L27) -> 125 | M28: =SUM(M4:M27) -> 115 | N28: =SUM(N4:N27) -> 0 | O28: =SUM(O4:O27) -> 0 | P28: =SUM(P4:P27) -> 0
A29: Total/Week | B29: =((B28/100)*5+C28/100+D28/100) -> 50 | E29: 64.55/74.2 | H29: =((H28/100)*5+I28/100+J28/100) -> 124 | K29: =((K28/100)*5+L28/100+M28/100) -> 5.9 | N29: =((N28/100)*5+O28/100+P28/100) -> 0
A30: Total/Year | B30: =B29*52.14 -> 2607 | E30: 3357/3869 | H30: =H29*52.14 -> 6465.36 | K30: =K29*52.14 -> 307.626 | N30: =N29*52.14 -> 0

Sheet Schedules - Office
A1: Hour of Day (Time) | B1: Schedule for Occupancy | E1: Schedule for Lighting/Receptacle | H1: Schedule for HVAC System | K1: Schedule for Service Hot Water | N1: Schedule for Elevator
B2: Percent of Maximum Load | E2: Percent of Maximum Load | K2: Percent of Maximum Load | N2: Percent of Maximum Load
B3: Wk | C3: Sat | D3: Sun | E3: Wk | F3: Sat | G3: Sun | H3: Wk | I3: Sat | J3: Sun | K3: Wk | L3: Sat | M3: Sun | N3: Wk | O3: Sat | P3: Sun
A4: 1 (12-1am) | B4: 0 | C4: 0 | D4: 0 | E4: 5 | F4: 5 | G4: 5 | H4: Off | I4: Off | J4: Off | K4: 5 | L4: 5 | M4: 4 | N4: 0 | O4: 0 | P4: 0
A5: 2 (1-2am) | B5: 0 | C5: 0 | D5: 0 | E5: 5 | F5: 5 | G5: 5 | H5: Off | I5: Off | J5: Off | K5: 5 | L5: 5 | M5: 4 | N5: 0 | O5: 0 | P5: 0
A6: 3 (2-3am) | B6: 0 | C6: 0 | D6: 0 | E6: 5 | F6: 5 | G6: 5 | H6: Off | I6: Off | J6: Off | K6: 5 | L6: 5 | M6: 4 | N6: 0 | O6: 0 | P6: 0
A7: 4 (3-4am) | B7: 0 | C7: 0 | D7: 0 | E7: 5 | F7: 5 | G7: 5 | H7: Off | I7: Off | J7: Off | K7: 5 | L7: 5 | M7: 4 | N7: 0 | O7: 0 | P7: 0
A8: 5 (4-5am) | B8: 0 | C8: 0 | D8: 0 | E8: 5 | F8: 5 | G8: 5 | H8: Off | I8: Off | J8: Off | K8: 5 | L8: 5 | M8: 4 | N8: 0 | O8: 0 | P8: 0
A9: 6 (5-6am) | B9: 0 | C9: 0 | D9: 0 | E9: 10 | F9: 5 | G9: 5 | H9: Off | I9: Off | J9: Off | K9: 8 | L9: 8 | M9: 7 | N9: 0 | O9: 0 | P9: 0
A10: 7 (6-7am) | B10: 10 | C10: 10 | D10: 5 | E10: 10 | F10: 10 | G10: 5 | H10: On | I10: On | J10: Off | K10: 7 | L10: 7 | M10: 4 | N10: 0 | O10: 0 | P10: 0
A11: 8 (7-8am) | B11: 20 | C11: 10 | D11: 5 | E11: 30 | F11: 10 | G11: 5 | H11: On | I11: On | J11: Off | K11: 19 | L11: 11 | M11: 4 | N11: 35 | O11: 16 | P11: 0
A12: 9 (8-9am) | B12: 95 | C12: 30 | D12: 5 | E12: 65/95 | F12: 30 | G12: 5 | H12: On | I12: On | J12: Off | K12: 35 | L12: 15 | M12: 4 | N12: 69 | O12: 14 | P12: 0
A13: 10 (9-10am) | B13: 95 | C13: 30 | D13: 5 | E13: 65/95 | F13: 30 | G13: 5 | H13: On | I13: On | J13: Off | K13: 38 | L13: 21 | M13: 4 | N13: 43 | O13: 21 | P13: 0
A14: 11 (10-11am) | B14: 95 | C14: 30 | D14: 5 | E14: 65/95 | F14: 30 | G14: 5 | H14: On | I14: On | J14: Off | K14: 39 | L14: 19 | M14: 4 | N14: 37 | O14: 18 | P14: 0
A15: 12 (11-12pm) | B15: 95 | C15: 30 | D15: 5 | E15: 65/95 | F15: 30 | G15: 5 | H15: On | I15: On | J15: Off | K15: 47 | L15: 23 | M15: 6 | N15: 43 | O15: 25 | P15: 0
A16: 13 (12-1pm) | B16: 50 | C16: 10 | D16: 5 | E16: 55/80 | F16: 15 | G16: 5 | H16: On | I16: On | J16: Off | K16: 57 | L16: 20 | M16: 6 | N16: 58 | O16: 21 | P16: 0
A17: 14 (1-2pm) | B17: 95 | C17: 10 | D17: 5 | E17: 65/95 | F17: 15 | G17: 5 | H17: On | I17: On | J17: Off | K17: 54 | L17: 19 | M17: 9 | N17: 48 | O17: 13 | P17: 0
A18: 15 (2-3pm) | B18: 95 | C18: 10 | D18: 5 | E18: 65/95 | F18: 15 | G18: 5 | H18: On | I18: On | J18: Off | K18: 34 | L18: 15 | M18: 6 | N18: 37 | O18: 8 | P18: 0
A19: 16 (3-4pm) | B19: 95 | C19: 10 | D19: 5 | E19: 65/95 | F19: 15 | G19: 5 | H19: On | I19: On | J19: Off | K19: 33 | L19: 12 | M19: 4 | N19: 37 | O19: 4 | P19: 0
A20: 17 (4-5pm) | B20: 95 | C20: 10 | D20: 5 | E20: 65/95 | F20: 15 | G20: 5 | H20: On | I20: On | J20: Off | K20: 44 | L20: 14 | M20: 4 | N20: 46 | O20: 5 | P20: 0
A21: 18 (5-6pm) | B21: 30 | C21: 5 | D21: 5 | E21: 35/50 | F21: 5 | G21: 5 | H21: On | I21: On | J21: Off | K21: 26 | L21: 7 | M21: 4 | N21: 62 | O21: 6 | P21: 0
A22: 19 (6-7pm) | B22: 10 | C22: 5 | D22: 0 | E22: 30 | F22: 5 | G22: 5 | H22: On | I22: Off | J22: Off | K22: 21 | L22: 7 | M22: 4 | N22: 20 | O22: 0 | P22: 0
A23: 20 (7-8pm) | B23: 10 | C23: 0 | D23: 0 | E23: 30 | F23: 5 | G23: 5 | H23: On | I23: Off | J23: Off | K23: 15 | L23: 7 | M23: 4 | N23: 12 | O23: 0 | P23: 0
A24: 21 (8-9pm) | B24: 10 | C24: 0 | D24: 0 | E24: 20 | F24: 5 | G24: 5 | H24: On | I24: Off | J24: Off | K24: 17 | L24: 7 | M24: 4 | N24: 4 | O24: 0 | P24: 0
A25: 22 (9-10pm) | B25: 10 | C25: 0 | D25: 0 | E25: 20 | F25: 5 | G25: 5 | H25: On | I25: Off | J25: Off | K25: 8 | L25: 9 | M25: 7 | N25: 4 | O25: 0 | P25: 0
A26: 23 (10-11pm) | B26: 5 | C26: 0 | D26: 0 | E26: 10 | F26: 5 | G26: 5 | H26: Off | I26: Off | J26: Off | K26: 5 | L26: 5 | M26: 4 | N26: 0 | O26: 0 | P26: 0
A27: 24 (11-12am) | B27: 5 | C27: 0 | D27: 0 | E27: 5 | F27: 5 | G27: 5 | H27: Off | I27: Off | J27: Off | K27: 5 | L27: 5 | M27: 4 | N27: 0 | O27: 0 | P27: 0
A28: Total/Day | B28: =SUM(B4:B27) -> 920 | C28: =SUM(C4:C27) -> 200 | D28: =SUM(D4:D27) -> 60 | E28: 800/1040 | F28: 280 | G28: 120 | H28: 1600 | I28: 1200 | J28: 0 | K28: =SUM(K4:K27) -> 537 | L28: =SUM(L4:L27) -> 256 | M28: =SUM(M4:M27) -> 113 | N28: =SUM(N4:N27) -> 555 | O28: =SUM(O4:O27) -> 151 | P28: =SUM(P4:P27) -> 0
A29: Total/Week | B29: =((B28/100)*5+C28/100+D28/100) -> 48.6 | E29: 44.00/56.00 | H29: =((H28/100)*5+I28/100+J28/100) -> 92 | K29: =((K28/100)*5+L28/100+M28/100) -> 30.54 | N29: =((N28/100)*5+O28/100+P28/100) -> 29.26
A30: Total/Year | B30: =B29*52.14 -> 2534.004 | E30: 2288/2920 | H30: =H29*52.14 -> 4796.88 | K30: =K29*52.14 -> 1592.3556 | N30: =N29*52.14 -> 1525.6164

Sheet Schedules - Retail
A1: Hour of Day (Time) | B1: Schedule for Occupancy | E1: Schedule for Lighting/Receptacle | H1: Schedule for HVAC System | K1: Schedule for Service Hot Water | N1: Schedule for Elevator
B2: Percent of Maximum Load | E2: Percent of Maximum Load | K2: Percent of Maximum Load | N2: Percent of Maximum Load
B3: Wk | C3: Sat | D3: Sun | E3: Wk | F3: Sat | G3: Sun | H3: Wk | I3: Sat | J3: Sun | K3: Wk | L3: Sat | M3: Sun | N3: Wk | O3: Sat | P3: Sun
A4: 1 (12-1am) | B4: 0 | C4: 0 | D4: 0 | E4: 5 | F4: 5 | G4: 5 | H4: Off | I4: Off | J4: Off | K4: 4 | L4: 11 | M4: 7 | N4: 0 | O4: 0 | P4: 0
A5: 2 (1-2am) | B5: 0 | C5: 0 | D5: 0 | E5: 5 | F5: 5 | G5: 5 | H5: Off | I5: Off | J5: Off | K5: 5 | L5: 10 | M5: 7 | N5: 0 | O5: 0 | P5: 0
A6: 3 (2-3am) | B6: 0 | C6: 0 | D6: 0 | E6: 5 | F6: 5 | G6: 5 | H6: Off | I6: Off | J6: Off | K6: 5 | L6: 8 | M6: 7 | N6: 0 | O6: 0 | P6: 0
A7: 4 (3-4am) | B7: 0 | C7: 0 | D7: 0 | E7: 5 | F7: 5 | G7: 5 | H7: Off | I7: Off | J7: Off | K7: 4 | L7: 6 | M7: 6 | N7: 0 | O7: 0 | P7: 0
A8: 5 (4-5am) | B8: 0 | C8: 0 | D8: 0 | E8: 5 | F8: 5 | G8: 5 | H8: Off | I8: Off | J8: Off | K8: 4 | L8: 6 | M8: 6 | N8: 0 | O8: 0 | P8: 0
A9: 6 (5-6am) | B9: 0 | C9: 0 | D9: 0 | E9: 5 | F9: 5 | G9: 5 | H9: Off | I9: Off | J9: Off | K9: 4 | L9: 6 | M9: 6 | N9: 0 | O9: 0 | P9: 0
A10: 7 (6-7am) | B10: 0 | C10: 0 | D10: 0 | E10: 5 | F10: 5 | G10: 5 | H10: On | I10: On | J10: Off | K10: 4 | L10: 7 | M10: 7 | N10: 0 | O10: 0 | P10: 0
A11: 8 (7-8am) | B11: 10 | C11: 10 | D11: 0 | E11: 20 | F11: 10 | G11: 5 | H11: On | I11: On | J11: Off | K11: 15 | L11: 20 | M11: 10 | N11: 12 | O11: 9 | P11: 0
A12: 9 (8-9am) | B12: 20 | C12: 20 | D12: 0 | E12: 50 | F12: 30 | G12: 10 | H12: On | I12: On | J12: On | K12: 23 | L12: 24 | M12: 12 | N12: 22 | O12: 21 | P12: 0
A13: 10 (9-10am) | B13: 50 | C13: 50 | D13: 10 | E13: 85/90 | F13: 55/60 | G13: 10 | H13: On | I13: On | J13: On | K13: 32 | L13: 27 | M13: 14 | N13: 64 | O13: 56 | P13: 11
A14: 11 (10-11am) | B14: 50 | C14: 60 | D14: 20 | E14: 85/90 | F14: 85/90 | G14: 40 | H14: On | I14: On | J14: On | K14: 41 | L14: 42 | M14: 29 | N14: 74 | O14: 66 | P14: 13
A15: 12 (11-12pm) | B15: 70 | C15: 80 | D15: 20 | E15: 85/90 | F15: 85/90 | G15: 40 | H15: On | I15: On | J15: On | K15: 57 | L15: 54 | M15: 31 | N15: 68 | O15: 68 | P15: 35
A16: 13 (12-1pm) | B16: 70 | C16: 80 | D16: 40 | E16: 85/90 | F16: 85/90 | G16: 55/60 | H16: On | I16: On | J16: On | K16: 62 | L16: 59 | M16: 36 | N16: 68 | O16: 68 | P16: 37
A17: 14 (1-2pm) | B17: 70 | C17: 80 | D17: 40 | E17: 85/90 | F17: 85/90 | G17: 55/60 | H17: On | I17: On | J17: On | K17: 61 | L17: 60 | M17: 36 | N17: 71 | O17: 69 | P17: 37
A18: 15 (2-3pm) | B18: 70 | C18: 80 | D18: 40 | E18: 85/90 | F18: 85/90 | G18: 55/60 | H18: On | I18: On | J18: On | K18: 50 | L18: 49 | M18: 34 | N18: 72 | O18: 70 | P18: 39
A19: 16 (3-4pm) | B19: 80 | C19: 80 | D19: 40 | E19: 85/90 | F19: 85/90 | G19: 55/60 | H19: On | I19: On | J19: On | K19: 45 | L19: 48 | M19: 35 | N19: 72 | O19: 69 | P19: 41
A20: 17 (4-5pm) | B20: 70 | C20: 80 | D20: 40 | E20: 85/90 | F20: 85/90 | G20: 55/60 | H20: On | I20: On | J20: On | K20: 46 | L20: 47 | M20: 37 | N20: 73 | O20: 66 | P20: 38
A21: 18 (5-6pm) | B21: 50 | C21: 60 | D21: 20 | E21: 85/90 | F21: 85/90 | G21: 40 | H21: On | I21: On | J21: Off | K21: 47 | L21: 46 | M21: 34 | N21: 68 | O21: 58 | P21: 34
A22: 19 (6-7pm) | B22: 50 | C22: 20 | D22: 10 | E22: 55/60 | F22: 50 | G22: 20 | H22: On | I22: On | J22: Off | K22: 42 | L22: 44 | M22: 25 | N22: 68 | O22: 47 | P22: 3
A23: 20 (7-8pm) | B23: 30 | C23: 20 | D23: 0 | E23: 55/60 | F23: 30 | G23: 5 | H23: On | I23: On | J23: Off | K23: 34 | L23: 36 | M23: 27 | N23: 58 | O23: 43 | P23: 0
A24: 21 (8-9pm) | B24: 30 | C24: 20 | D24: 0 | E24: 50 | F24: 30 | G24: 5 | H24: On | I24: On | J24: Off | K24: 33 | L24: 29 | M24: 21 | N24: 54 | O24: 43 | P24: 0
A25: 22 (9-10pm) | B25: 0 | C25: 10 | D25: 0 | E25: 20 | F25: 10 | G25: 5 | H25: Off | I25: On | J25: Off | K25: 23 | L25: 22 | M25: 16 | N25: 0 | O25: 8 | P25: 0
A26: 23 (10-11pm) | B26: 0 | C26: 0 | D26: 0 | E26: 5 | F26: 5 | G26: 5 | H26: Off | I26: Off | J26: Off | K26: 13 | L26: 16 | M26: 10 | N26: 0 | O26: 0 | P26: 0
A27: 24 (11-12am) | B27: 0 | C27: 0 | D27: 0 | E27: 5 | F27: 5 | G27: 5 | H27: Off | I27: Off | J27: Off | K27: 8 | L27: 13 | M27: 6 | N27: 0 | O27: 0 | P27: 0
A28: Total/Day | B28: =SUM(B4:B27) -> 720 | C28: =SUM(C4:C27) -> 750 | D28: =SUM(D4:D27) -> 280 | E28: 1060/1155 | F28: 940/985 | G28: 500/525 | H28: 1500 | I28: 1600 | J28: 900 | K28: =SUM(K4:K27) -> 662 | L28: =SUM(L4:L27) -> 690 | M28: =SUM(M4:M27) -> 459 | N28: =SUM(N4:N27) -> 844 | O28: =SUM(O4:O27) -> 761 | P28: =SUM(P4:P27) -> 288
A29: Total/Week | B29: =((B28/100)*5+C28/100+D28/100) -> 46.3 | E29: 67.40/70.85 | H29: =((H28/100)*5+I28/100+J28/100) -> 100 | K29: =((K28/100)*5+L28/100+M28/100) -> 44.59 | N29: =((N28/100)*5+O28/100+P28/100) -> 52.69
A30: Total/Year | B30: =B29*52.14 -> 2414.082 | E30: 3505/3694 | H30: =H29*52.14 -> 5214 | K30: =K29*52.14 -> 2324.9226 | N30: =N29*52.14 -> 2747.2566

Sheet Schedules - Dwelling Unit
A1: Hour of Day (Time) | B1: Schedule for Occupancy | E1: Schedule for Lighting/Receptacle | H1: Daily Thermostat Schedule | J1: Schedule for Service Hot Water
B2: Percent of Maximum Load | E2: Percent of Maximum Load | J2: Percent of Maximum Load
B3: Wk | C3: Sat | D3: Sun | E3: Wk | F3: Sat | G3: Sun | H3: Cooling | I3: Heating | J3: Wk | K3: Sat | L3: Sun
A4: 1 (12-1am) | B4: 1.6 | C4: 1.6 | D4: 1.6 | E4: 5 | F4: 5 | G4: 5 | H4: 70 | I4: 78 | J4: 5 | K4: 5 | L4: 5
A5: 2 (1-2am) | B5: 1.6 | C5: 1.6 | D5: 1.6 | E5: 5 | F5: 5 | G5: 5 | H5: 70 | I5: 78 | J5: 5 | K5: 5 | L5: 5
A6: 3 (2-3am) | B6: 1.6 | C6: 1.6 | D6: 1.6 | E6: 5 | F6: 5 | G6: 5 | H6: 70 | I6: 78 | J6: 5 | K6: 5 | L6: 5
A7: 4 (3-4am) | B7: 1.6 | C7: 1.6 | D7: 1.6 | E7: 5 | F7: 5 | G7: 5 | H7: 70 | I7: 78 | J7: 5 | K7: 5 | L7: 5
A8: 5 (4-5am) | B8: 1.6 | C8: 1.6 | D8: 1.6 | E8: 5 | F8: 5 | G8: 5 | H8: 70 | I8: 78 | J8: 5 | K8: 5 | L8: 5
A9: 6 (5-6am) | B9: 1.6 | C9: 1.6 | D9: 1.6 | E9: 5 | F9: 5 | G9: 5 | H9: 70 | I9: 78 | J9: 5 | K9: 5 | L9: 5
A10: 7 (6-7am) | B10: 7.7 | C10: 7.7 | D10: 7.7 | E10: 5 | F10: 5 | G10: 5 | H10: 72 | I10: 78 | J10: 30 | K10: 30 | L10: 30
A11: 8 (7-8am) | B11: 14 | C11: 14 | D11: 14 | E11: 5 | F11: 5 | G11: 5 | H11: 72 | I11: 78 | J11: 50 | K11: 50 | L11: 50
A12: 9 (8-9am) | B12: 14 | C12: 14 | D12: 14 | E12: 50 | F12: 50 | G12: 50 | H12: 72 | I12: 78 | J12: 40 | K12: 40 | L12: 40
A13: 10 (9-10am) | B13: 10.8 | C13: 10.8 | D13: 10.8 | E13: 50 | F13: 50 | G13: 50 | H13: 72 | I13: 80 | J13: 30 | K13: 30 | L13: 30
A14: 11 (10-11am) | B14: 10.8 | C14: 10.8 | D14: 10.8 | E14: 50 | F14: 50 | G14: 50 | H14: 72 | I14: 80 | J14: 30 | K14: 30 | L14: 30
A15: 12 (11-12pm) | B15: 10.8 | C15: 10.8 | D15: 10.8 | E15: 50 | F15: 50 | G15: 50 | H15: 72 | I15: 80 | J15: 35 | K15: 35 | L15: 35
... A27: 24 (11-12am) | B27: 1.6 | C27: 1.6 | D27: 1.6 | E27: 5 | F27: 5 | G27: 5 | H27: 70 | I27: 78 | J27: 5 | K27: 5 | L27: 5
A28: Total/Day | B28: =SUM(B4:B27) -> 234 | C28: =SUM(C4:C27) -> 234 | D28: =SUM(D4:D27) -> 234 | E28: =SUM(E4:E27) -> 580 | F28: =SUM(F4:F27) -> 580 | G28: =SUM(G4:G27) -> 580 | J28: =SUM(J4:J27) -> 670 | K28: =SUM(K4:K27) -> 670 | L28: =SUM(L4:L27) -> 670
A29: Total/Week | B29: =((B28/100)*5+C28/100+D28/100) -> 16.38 | E29: =((E28/100)*5+F28/100+G28/100) -> 40.6 | J29: =((J28/100)*5+K28/100+L28/100) -> 46.9
A30: Total/Year | B30: =B29*52.14 -> 854.0532 | E30: =E29*52.14 -> 2116.884 | J30: =J29*52.14 -> 2445.366

Sheet Version Control
A1: Version # | B1: Issue Date | C1: Fixes
A2: Version 1 | B2: 43963
A3: Version 2 | B3: 43965 | C3: 1,2,3. - edit cell B7, add dropdown cell C7
C4: 3d. - edit cell/formula in D18
C5: 4. - unlock cell D17
C6: 5b. - edit cells C18:L18
C7: 6c. - unlock ability to add rows
C8: 6d.1 - align with spaces/lpd (not blg area)
C9: 6f. - add formulas to C20:D21
C10: 6g. - add formula for baseline
A11: Version 3 | B11: 43973 | C11: 6b. - add more fenestration rows
C12: 6b. - fixed cell M22 for no skylight
C13: 6c1. - rename tab, remove ability to add rows
C14: 6c2. - add new tab for additional opaque rows
C15: 6d.1 - align all rows with spaces/lpd (not blg area)
C16: 6d.1 - edit formula for cell B31
C17: Instructions for HVAC_Cover - added Items 5 & 6
A18: Version 4 | B18: 44125 | C18: 4. - edited H19:I20 to consistant units of kBTU, instead of kwh and therm
C19: 5b. - added missing formula to cell d11
A20: Version 5 | B20: 44175 | C20: UNPROTECT WORKBOOK
A21: Version 6 | B21: 45057 | C21: Edited "Lighting Lookup" tab for Multifamily Dwelling Unit LPD from 0.70 to 1.07 (per Table G3.7)
B22: 45063 | C22: Edited 6d.1 & 6d.2, corrected sum formula for building and space areas
A23: Verson 7 | B23: 45148 | C23: Unprotected "HVAC Air-side" tab
C24: Protected "HVAC_Cover" tab

Sheet 1,2,3 Information
A2: Enter information for sections 1, 2 and 3 - incorporate in the drawing set.
A3: Must be typewritten
A4: 1 | B4: Location Information
B5: House No(s) 79 | C5: Street Name WINTHROP STREET
B6: Borough BROOKLYN | C6: Block 5045 | D6: Lot 72 | E6: BIN 3115681 | G6: CB No. 309
B7: Job Type (NB, Alt, etc.) | C7: New Building
A10: 2a | B10: Applicant Information
B11: Last Name FAYBYSHENKO | D11: First Name GENNADIY | I11: Middle Initial B.
B12: Business Name CHOSEN MEP, CORP. | F12: Business Email
B13: Business Address 31-00 47TH AVENUE SUITE #3100 | F13: Business Telephone 347-766-5010
B14: City LONG ISLAND CITY | C14: State NY | E14: Zip 11101
B15: Email INFO@CHOSENMEP.COM | G15: License Number 091045
A18: 2b | B18: Modeling Firm
B19: Last Name (lead modeler) BEREGOVYKH | D19: First Name (lead modeler) NIKITA | I19: Middle Initial
B20: Business Name LIBER CREATIVE LLC | F20: Email (lead modeler) NVBEREGOVYKH@LIBERPICT.COM
B21: Business Address 2306 OCEAN AVENUE | F21: Telephone (lead modeler) 929-356-1398
B22: City BROOKLYN | C22: State NY | E22: Zip 11229
A25: 3a | B25: Energy Modeling Information | F25: 3b | G25: Energy Modeling Information per Modeled Square Feet
B26: Modeling Protocol (Sect 11 or Apx G) | C26: =IF(Path="","Select Path on tab 4. Compliance",Path) -> Appendix G PRM | G26: Proposed | H26: Total Energy Cost ($/sf) | I26: ='4. Compliance'!G12/'1,2,3 Information'!C32 -> 2.1859941
B27: Modeling Software & version | C27: EnergyPlus Version 25.1.0-1c11a3d85f | H27: Site EUI (kBtu/sf) | I27: =('5b. Usage Summary'!G17*3.412+'5b. Usage Summary'!H17*100)/'1,2,3 Information'!C32 -> 29.834739
B28: Weather File | C28: NEW YORK LAGUARDIA ARPT NY USA TMY3 | H28: Source EUI (kBtu/sf) | I28: =('5b. Usage Summary'!G17*3.412*2.55+'5b. Usage Summary'!H17*100*1.05)/'1,2,3 Information'!C32 -> 76.078585
B29: Proposed Unmet Load Hours | C29: 70.66 | H29: GHG (tCO2e/sf) | I29: ='3d. LL97 GHG Summary'!E33/'1,2,3 Information'!C32 -> 0.0025267016
B30: Baseline Unmet Load Hours | C30: 34.66 | G30: Baseline | H30: Total Energy Cost ($/sf) | I30: ='4. Compliance'!E12/'1,2,3 Information'!C32 -> 3.4558825
B31: Gross Square Feet | C31: 12381.63 | H31: Site EUI (kBtu/sf) | I31: =('5b. Usage Summary'!C17*3.412+'5b. Usage Summary'!D17*100)/'1,2,3 Information'!C32 -> 80.627983
B32: Modeled Square Feet | C32: 11690.791 | H32: Source EUI (kBtu/sf) | I32: =('5b. Usage Summary'!C17*3.412*2.55+'5b. Usage Summary'!D17*100*1.05)/'1,2,3 Information'!C32 -> 143.02646
B33: Conditioned Square Feet | C33: 11169.925 | H33: GHG (tCO2e/sf) | I33: =SUM('3d. LL97 GHG Summary'!J24:J28)/'1,2,3 Information'!C32 -> 0.0055109706
B34: Semi-heated Square Feet | C34: 0 | G34: % Savings | H34: Total Energy Cost ($/sf) | I34: =(I30-I26)/I30 -> 0.36745706
B35: Unconditioned Square Feet | C35: 520.866 | H35: Site EUI (kBtu/sf) | I35: =(I31-I27)/I31 -> 0.62997041
H36: Source EUI (kBtu/sf) | I36: =(I32-I28)/I32 -> 0.46808036
A37: 3c | B37: List all Job Numbers Associated with this Model | H37: GHG (tCO2e/sf) | I37: =(I33-I29)/I33 -> 0.54151423
B38: ARCHITECTURAL | C38: B01304513-P1
B39: MECHANICAL | C39: B01304513-P6
B40: PLUMBING | C40: B01304513-P5

Sheet 3d. LL97 GHG Summary
A3: FOR INFORMATIONAL PURPOSES ONLY: NOT REQUIRED FOR ENERGY CODE COMPLIANCE
B8: 3d | C8: Carbon Emissions Limit (LL97)
C9: Occupancy | D9: Total Gross SQFT per occupancy | F9: tCO2e limit (2024) | H9: tCO2e limit (2030)
F10: =IF(C10="","",VLOOKUP(C10,Lists!A134:B143,2,FALSE)) | H10: =IF(C10="","",VLOOKUP(C10,Lists!$A$133:$C$143,3,FALSE))
F11: =IF(C11="","",VLOOKUP(C11,Lists!$A$134:$F$144,2,FALSE)) | H11: =IF(C11="","",VLOOKUP(C11,Lists!$A$133:$C$143,3,FALSE))
F12: =IF(C12="","",VLOOKUP(C12,Lists!$A$134:$F$144,2,FALSE)) | H12: =IF(C12="","",VLOOKUP(C12,Lists!$A$133:$C$143,3,FALSE))
F13: =IF(C13="","",VLOOKUP(C13,Lists!$A$134:$F$144,2,FALSE)) | H13: =IF(C13="","",VLOOKUP(C13,Lists!$A$133:$C$143,3,FALSE))
F14: =IF(C14="","",VLOOKUP(C14,Lists!$A$134:$F$144,2,FALSE)) | H14: =IF(C14="","",VLOOKUP(C14,Lists!$A$133:$C$143,3,FALSE))
F15: =IF(C15="","",VLOOKUP(C15,Lists!$A$134:$F$144,2,FALSE)) | H15: =IF(C15="","",VLOOKUP(C15,Lists!$A$133:$C$143,3,FALSE))
F16: =IF(C16="","",VLOOKUP(C16,Lists!$A$134:$F$144,2,FALSE)) | H16: =IF(C16="","",VLOOKUP(C16,Lists!$A$133:$C$143,3,FALSE))
F17: =IF(C17="","",VLOOKUP(C17,Lists!$A$134:$F$144,2,FALSE)) | H17: =IF(C17="","",VLOOKUP(C17,Lists!$A$133:$C$143,3,FALSE))
C18: TOTAL | D18: =IF(D10="","",IF(SUM(D10:E17)='1,2,3 Information'!C31,SUM(D10:E17),"Total area does not align with GROSS FLOOR AREA of the building"))
C19: GHG Building Emission Limits | F19: =SUMPRODUCT(D10:D17,F10:F17) -> 0 | H19: =SUMPRODUCT(D10:D17,H10:H17) -> 0
C20: Proposed Building GHG (estimated from model) | F20: =SUM(F24:F28) -> 29.53914
B22: 3e | C22: Carbon Emissions Proposed Building (LL97) | G22: Carbon Emissions Baseline Building (LL97)
D23: (kBTU) | E23: tCO2e per kBTU | F23: tCO2e | H23: (kBTU) | I23: tCO2e per kBTU | J23: tCO2e
C24: Electricity (kwh) | D24: =IF('5b. Usage Summary'!$G$17="","",'5b. Usage Summary'!$G$17) -> 102225 | E24: 0.000288962 | F24: =IF(D24="","",E24*D24) -> 29.53914 | G24: Electricity (kwh) | H24: =IF('5b. Usage Summary'!$C$17="","",'5b. Usage Summary'!$C$17) -> 133325 | I24: 0.000288962 | J24: =IF(H24="","",I24*H24) -> 38.525859
C25: Natural Gas | D25: =IF('5b. Usage Summary'!$H$17="","",'5b. Usage Summary'!$H$17*100) -> 0 | E25: 5.311e-05 | F25: =IF(D25="","",E25*D25) -> 0 | G25: Natural Gas | H25: =IF('5b. Usage Summary'!$D$17="","",'5b. Usage Summary'!$D$17*100) -> 487700 | I25: 5.311e-05 | J25: =IF(H25="","",I25*H25) -> 25.901747
C26: #2 Fuel Oil | E26: 7.421e-05 | F26: =IF(D26="","",E26*D26) | G26: #2 Fuel Oil | I26: 7.421e-05 | J26: =IF(H26="","",I26*H26)
C27: #4 Fuel Oil | E27: 7.529e-05 | F27: =IF(D27="","",E27*D27) | G27: #4 Fuel Oil | I27: 7.529e-05 | J27: =IF(H27="","",I27*H27)
C28: District Steam | E28: 4.493e-05 | F28: =IF(D28="","",E28*D28) | G28: District Steam | I28: 4.493e-05 | J28: =IF(H28="","",I28*H28)
B30: 3e | C30: Carbon Emissions Information (LL97)
E31: tCO2e Limits for 2024-2029 | G31: tCO2e Limits for 2030-2034
C32: tCO2e Limit (LL97) | E32: =IF('3d. LL97 GHG Summary'!F19="","",'3d. LL97 GHG Summary'!F19) -> 0 | G32: =IF('3d. LL97 GHG Summary'!H19="","",'3d. LL97 GHG Summary'!H19) -> 0
C33: tCO2e for this Building | E33: =IF('5b. Usage Summary'!G17="","",SUM('3d. LL97 GHG Summary'!F24:F28)) -> 29.53914
C34: Does this building comply with LL97? | E34: =IF(E33="","",IF(E33="","",IF(AND(E33<E32,E33<G32),"This building is subject to meeting LL97 of 2019. The proposed design is estimated to comply with the Carbon Limits for 2024-2029 & 2030-2035.",IF(AND(E33<E32,E33>G32),"This building is subject to meeting LL97 of 2019. By 2030, this proposed design may not comply with the requirements of LL97 based on the estimated carbon emissions.","This building is subject to meeting LL97 of 2019. By 2024, this proposed design may not comply with the requirements of LL97 based on the estimated carbon emissions.")))) -> This building is subject to meeting LL97 of 2019. By 2024, this proposed design may not comply with the requirements of LL97 based on the estimated carbon emissions.
C36: **Total carbon emissions (tCO2e) for this building is an estimate for informational purposes based on the proposed occupancy, gross square footage, and modeled annual energy usage. The performance of the building will be affected by construction quality, occupancy, and operational impacts. Actual carbon emissions may be higher or lower than this estimate. **

Sheet 4. Compliance
A3: 4a. | B3: Energy Modeling Protocol (select)
B4: Appendix G PRM
A6: 4b. | B6: Purchased Energy Rates & Compliance Documentation
A7: Fuel | C7: Utility Rate Provider/Rate Structure (i.e ConEd) | D7: Virtual Utility Rate ($/unit) | E7: Baseline Design Total Charge ($) | F7: Virtual Utility Rate ($/unit) | G7: Proposed Design Total Charge ($) | H7: Supporting Doc. Location | I7: Model Output Report
A8: Electric | C8: Con Edison | D8: 0.25 | E8: ='5a. Baseline Rotations'!O23 -> 33332 | F8: 0.25 | G8: 25556 | H8: Energy Model (Appendix G) | I8: BEPU, BEPU-P
A9: Gas/Steam | C9: Con Edison | D9: 1.45 | E9: ='5a. Baseline Rotations'!O24 -> 7070 | H9: Energy Model (Appendix G) | I9: BEPU, BEPU-P
A10: Other - ($/kBTU) | E10: ='5a. Baseline Rotations'!O25 | H10: Energy Model (Appendix G) | I10: BEPU, BEPU-P
H11: COST SAVINGS | I11: COMPLIES?
A12: TOTAL | E12: =IF(SUM(E8:E10)=0,"",SUM(E8:E10)) -> 40402 | G12: =IF(SUM(G8:G10)=0,"",SUM(G8:G10)) -> 25556 | H12: =IF(E12="","",E12-G12) -> 14846 | I12: =IF(E12="","",IF(B4="Section 11 ECB",IF(G12<E12,"COMPLIES","DOES NOT COMPLY"),IF(D21<C21,"COMPLIES","DOES NOT COMPLY"))) -> COMPLIES
A15: 4c. | B15: Performance Cost Index - Appendix G ONLY | F15: 4d. | G15: Performance Source Energy Index - Appendix G ONLY
C16: Baseline Building | D16: Proposed Building | H16: Baseline Building | I16: Proposed Building
A17: Building Performance Factor | C17: =IF(D17="","",IF(D17="Weighted Average",D25,VLOOKUP(D17,Lists!M13:N22,2))) -> 0.67 | D17: Multifamily | F17: Building Performance Factor | H17: =IF(I17="","",IF(I17="Weighted Average",D27,VLOOKUP(I17,Lists!M13:O22,3))) -> 0.68 | I17: =IF(D17="","",D17) -> Multifamily
A18: Baseline Regulated Cost | C18: =IF(B4="Section 11 ECB","",IF(C20="","",C20-C19)) -> 39679.75 | D18: =IF(B4="Section 11 ECB","",IF(D20="","",D20-D19)) -> 24833.75 | F18: Baseline Regulated Source Energy | H18: =IF(B4="Section 11 ECB","",IF(I17="","",H20-H19)) -> 1646956.5 | I18: =IF(B4="Section 11 ECB","",IF(I17="","",I20-I19)) -> 864282.8
A19: Baseline Unregulated Cost | C19: =('5b. Usage Summary'!$C$7)*D8+('5b. Usage Summary'!$D$7)*D9 -> 722.25 | D19: =('5b. Usage Summary'!$G$7)*F8+('5b. Usage Summary'!$H$7)*F9 -> 722.25 | F19: Baseline Unregulated Source Energy | H19: =('5b. Usage Summary'!$C$7)*3.412*2.55+('5b. Usage Summary'!$D$7)*100*1.05 -> 25136.033 | I19: =('5b. Usage Summary'!$G$7)*3.412*2.55+('5b. Usage Summary'!$H$7)*100*1.05 -> 25136.033
A20: Total Energy Cost | C20: =IF(B4="Section 11 ECB","",E12) -> 40402 | D20: =IF(B4="Section 11 ECB","",G12) -> 25556 | F20: Total Source Energy | H20: =IF(B4="Section 11 ECB","",IF(I17="","",SUM('5b. Usage Summary'!C17*3.412*2.55,'5b. Usage Summary'!D17*100*1.05))) -> 1672092.5 | I20: =IF(B4="Section 11 ECB","",IF(I17="","",SUM('5b. Usage Summary'!G17*3.412*2.55,'5b. Usage Summary'!H17*100*1.05))) -> 889418.83
A21: Performance Cost Index | C21: =IF(C20="","",(C19+(C18*C17))/C20) -> 0.67589927 | D21: =IF(D20="","",D20/C20) -> 0.63254294 | F21: Performance Source Energy Index | H21: =IF(H20="","",(H19+(H18*H17))/H20) -> 0.68481046 | I21: =IF(I20="","",I20/H20) -> 0.53191964
A23: 4e. | B23: Weighted BPF | F23: 4f. | G23: Weighted Envelope Backstop (results from ComCheck)
A24: Space Classification | C24: Modeled Area | D24: Weighted BPF (energy cost) | F24: Allowable Margin (baseline)
A25: All Other | D25: =IF(AND(D17="Weighted Average",SUM(C25:C34)<>0),SUMPRODUCT(C25:C34,Lists!N13:N22)/SUM(C25:C34),"Input modeled areas for each space classification") -> Input modeled areas for each space classification | F25: Envelope Design (proposed)
A26: Dormitory | D26: Weighted BPF (source energy)
A27: Healthcare/ hospital | D27: =IF(AND(I17="Weighted Average",SUM(C25:C34)<>0),SUMPRODUCT(C25:C34,Lists!O13:O22)/SUM(C25:C34),"Input modeled areas for each space classification") -> Input modeled areas for each space classification
A28: Hotel/motel
A29: Multifamily | C29: 11690.791
A30: Office
A31: Restaurant
A32: Retail
A33: School
A34: Warehouse
A35: TOTAL | C35: =IF(SUM(C25:C34)<>'1,2,3 Information'!C32,"NOT EQUAL TO MODELED AREA",SUM(C25:C34)) -> 11690.791

Sheet 5a. Baseline Rotations
A2: INSTRUCTIONS: If the modeling parameters call for averaging 4 rotations, enter the data into each of the white columns. If the modeling protocol does not require averaging the 4 rotations, enter the data into only the column labeled "0'" (do not enter '0' into the columns labeled 90, 180, 270).
A4: 5a | B4: Baseline Rotations
A5: Baseline Model
C6: 0' | F6: 90' | I6: 180' | L6: 270' | O6: Average of 4 rotations | R6: Model Output Location (Report)
A7: Annual usage (kwh/therm/kBTU)
C8: kwh | D8: therm | E8: kBTU | F8: kwh | G8: therm | H8: kBTU | I8: kwh | J8: therm | K8: kBTU | L8: kwh | M8: therm | N8: kBTU | O8: kwh | P8: therm | Q8: kBTU
A9: Interior Lighting | C9: 29869 | D9: 0 | E9: 0 | O9: =IF(C9="","",IF(F9=0,C9,AVERAGE(C9,F9,I9,L9))) -> 29869 | P9: =IF(D9="","",IF(G9=0,D9,AVERAGE(D9,G9,J9,M9))) -> 0 | Q9: =IF(E9="","",IF(H9=0,E9,AVERAGE(E9,H9,K9,N9))) -> 0 | R9: BEPU
A10: Misc. Equip. Unregulated | C10: 2889 | D10: 0 | E10: 0 | O10: =IF(C10="","",IF(F10=0,C10,AVERAGE(C10,F10,I10,L10))) -> 2889 | P10: =IF(D10="","",IF(G10=0,D10,AVERAGE(D10,G10,J10,M10))) -> 0 | Q10: =IF(E10="","",IF(H10=0,E10,AVERAGE(E10,H10,K10,N10))) -> 0 | R10: BEPU
A11: Misc. Equip. Regulated | C11: 0 | D11: 0 | E11: 0 | O11: =IF(C11="","",IF(F11=0,C11,AVERAGE(C11,F11,I11,L11))) -> 0 | P11: =IF(D11="","",IF(G11=0,D11,AVERAGE(D11,G11,J11,M11))) -> 0 | Q11: =IF(E11="","",IF(H11=0,E11,AVERAGE(E11,H11,K11,N11))) -> 0 | R11: BEPU
A12: Space Heat | C12: 0 | D12: 3493 | E12: 0 | O12: =IF(C12="","",IF(F12=0,C12,AVERAGE(C12,F12,I12,L12))) -> 0 | P12: =IF(D12="","",IF(G12=0,D12,AVERAGE(D12,G12,J12,M12))) -> 3493 | Q12: =IF(E12="","",IF(H12=0,E12,AVERAGE(E12,H12,K12,N12))) -> 0 | R12: BEPU
A13: Space Cool | C13: 20828 | D13: 0 | E13: 0 | O13: =IF(C13="","",IF(F13=0,C13,AVERAGE(C13,F13,I13,L13))) -> 20828 | P13: =IF(D13="","",IF(G13=0,D13,AVERAGE(D13,G13,J13,M13))) -> 0 | Q13: =IF(E13="","",IF(H13=0,E13,AVERAGE(E13,H13,K13,N13))) -> 0 | R13: BEPU
A14: Heat Rejection | C14: 0 | D14: 0 | E14: 0 | O14: =IF(C14="","",IF(F14=0,C14,AVERAGE(C14,F14,I14,L14))) -> 0 | P14: =IF(D14="","",IF(G14=0,D14,AVERAGE(D14,G14,J14,M14))) -> 0 | Q14: =IF(E14="","",IF(H14=0,E14,AVERAGE(E14,H14,K14,N14))) -> 0 | R14: BEPU
A15: Pumps & Misc | C15: 5433 | D15: 0 | E15: 0 | O15: =IF(C15="","",IF(F15=0,C15,AVERAGE(C15,F15,I15,L15))) -> 5433 | P15: =IF(D15="","",IF(G15=0,D15,AVERAGE(D15,G15,J15,M15))) -> 0 | Q15: =IF(E15="","",IF(H15=0,E15,AVERAGE(E15,H15,K15,N15))) -> 0 | R15: BEPU
A16: Vent Fans | C16: 73953 | D16: 0 | E16: 0 | O16: =IF(C16="","",IF(F16=0,C16,AVERAGE(C16,F16,I16,L16))) -> 73953 | P16: =IF(D16="","",IF(G16=0,D16,AVERAGE(D16,G16,J16,M16))) -> 0 | Q16: =IF(E16="","",IF(H16=0,E16,AVERAGE(E16,H16,K16,N16))) -> 0 | R16: BEPU
A17: Dom. Hot Water | C17: 75 | D17: 1384 | E17: 0 | O17: =IF(C17="","",IF(F17=0,C17,AVERAGE(C17,F17,I17,L17))) -> 75 | P17: =IF(D17="","",IF(G17=0,D17,AVERAGE(D17,G17,J17,M17))) -> 1384 | Q17: =IF(E17="","",IF(H17=0,E17,AVERAGE(E17,H17,K17,N17))) -> 0 | R17: BEPU
A18: Exterior Lighting | C18: 278 | D18: 0 | E18: 0 | O18: =IF(C18="","",IF(F18=0,C18,AVERAGE(C18,F18,I18,L18))) -> 278 | P18: =IF(D18="","",IF(G18=0,D18,AVERAGE(D18,G18,J18,M18))) -> 0 | Q18: =IF(E18="","",IF(H18=0,E18,AVERAGE(E18,H18,K18,N18))) -> 0 | R18: BEPU
A19: Exterior Misc. | C19: 0 | D19: 0 | E19: 0 | O19: =IF(C19="","",IF(F19=0,C19,AVERAGE(C19,F19,I19,L19))) -> 0 | P19: =IF(D19="","",IF(G19=0,D19,AVERAGE(D19,G19,J19,M19))) -> 0 | Q19: =IF(E19="","",IF(H19=0,E19,AVERAGE(E19,H19,K19,N19))) -> 0 | R19: BEPU
A20: TOTAL | C20: =IF(SUM(C9:C19)=0,"",SUM(C9:C19)) -> 133325 | D20: =IF(SUM(D9:D19)=0,"",SUM(D9:D19)) -> 4877 | E20: =IF(SUM(E9:E19)=0,"",SUM(E9:E19)) | F20: =IF(SUM(F9:F19)=0,"",SUM(F9:F19)) | G20: =IF(SUM(G9:G19)=0,"",SUM(G9:G19)) | H20: =IF(SUM(H9:H19)=0,"",SUM(H9:H19)) | I20: =IF(SUM(I9:I19)=0,"",SUM(I9:I19)) | J20: =IF(SUM(J9:J19)=0,"",SUM(J9:J19)) | ... N20: =IF(SUM(N9:N19)=0,"",SUM(N9:N19)) | O20: =IF(C20="","",IF(F20=0,C20,AVERAGE(C20,F20,I20,L20))) -> 133325 | P20: =IF(D20="","",IF(G20=0,D20,AVERAGE(D20,G20,J20,M20))) -> 4877 | Q20: =IF(E20="","",IF(H20=0,E20,AVERAGE(E20,H20,K20,N20))) | R20: BEPU
A21: Annual cost ($)
A23: Electric | C23: 33332 | O23: =IF(C23="","",IF(F23="",C23,AVERAGE(C23:M23))) -> 33332 | R23: BEPU
A24: Gas/Steam | C24: 7070 | O24: =IF(C24="","",IF(F24="",C24,AVERAGE(C24:M24))) -> 7070 | R24: BEPU
A25: Other | O25: =IF(C25="","",IF(F25="",C25,AVERAGE(C25:M25))) | R25: BEPU
A26: TOTAL | C26: =IF(C23="","",SUM(C23:D25)) -> 40402 | F26: =IF(F23="","",SUM(F23:G25)) | I26: =IF(I23="","",SUM(I23:J25)) | L26: =IF(L23="","",SUM(L23:M25)) | O26: =IF(O23="","",SUM(O23:P25)) -> 40402 | R26: BEPU

Sheet 5b. Usage Summary
A2: 5b | B2: Energy Modeling Usage Summary
A3: =CONCATENATE("Compliance based on ",IF(Path="","",Path)) -> Compliance based on Appendix G PRM
C4: Baseline Model | G4: Proposed Model
C5: Electric Usage (kwh) | D5: Gas/Steam Usage (Therm) | E5: Other (i.e. chilled water) (kBTU) | F5: % Usage | G5: Electric Usage (kwh) | H5: Gas/Steam Usage (Therm) | I5: Other (i.e. chilled water) (kBTU) | J5: % Usage | K5: Energy Savings Per End Use (%) | L5: Cost Savings per End Use (%) | M5: Model Output Location (Report)
A6: Interior Lighting | C6: =IF('5a. Baseline Rotations'!O9="","",'5a. Baseline Rotations'!O9) -> 29869 | D6: =IF('5a. Baseline Rotations'!P9="","",'5a. Baseline Rotations'!P9) -> 0 | E6: =IF('5a. Baseline Rotations'!Q9="","",'5a. Baseline Rotations'!Q9) -> 0 | F6: =IF(C6="","",(C6*3.412+D6*100+E6)/($C$17*3.412+$D$17*100+$E$17)) -> 0.1081185 | G6: 3408 | H6: 0 | I6: 0 | J6: =IF(G6="","",(G6*3.412+H6*100+I6)/($G$17*3.412+$H$17*100+$I$17)) -> 0.033338224 | K6: =IF(AND(C6="",D6=""),"",((C6-G6)*3.412+(D6-H6)*100+(E6-I6))/(($C$17-$G$17)*3.412+($D$17-$H$17)*100+($E$17-$I$17))) -> 0.15204265 | L6: =IF(AND(C6="",D6=""),"",(($C6-$G6)*'4. Compliance'!$F$8+($D6-$H6)*'4. Compliance'!$F$9+($E6-$I6)*'4. Compliance'!$F$10)/(($C$17-$G$17)*'4. Compliance'!$F$8+($D$17-$H$17)*'4. Compliance'!$F$9+($E$17-$I$17)*'4. Compliance'!$F$10)) -> 0.85083601 | M6: BEPU, BEPU-P
A7: Misc. Equip. Unregulated | C7: =IF('5a. Baseline Rotations'!O10="","",'5a. Baseline Rotations'!O10) -> 2889 | D7: =IF('5a. Baseline Rotations'!P10="","",'5a. Baseline Rotations'!P10) -> 0 | E7: =IF('5a. Baseline Rotations'!Q10="","",'5a. Baseline Rotations'!Q10) -> 0 | F7: =IF(C7="","",(C7*3.412+D7*100+E7)/($C$17*3.412+$D$17*100+$E$17)) -> 0.010457476 | G7: 2889 | H7: 0 | I7: 0 | J7: =IF(G7="","",(G7*3.412+H7*100+I7)/($G$17*3.412+$H$17*100+$I$17)) -> 0.028261189 | K7: =IF(AND(C7="",D7=""),"",((C7-G7)*3.412+(D7-H7)*100+(E7-I7))/(($C$17-$G$17)*3.412+($D$17-$H$17)*100+($E$17-$I$17))) -> 0 | L7: =IF(AND(C7="",D7=""),"",(($C7-$G7)*'4. Compliance'!$F$8+($D7-$H7)*'4. Compliance'!$F$9+($E7-$I7)*'4. Compliance'!$F$10)/(($C$17-$G$17)*'4. Compliance'!$F$8+($D$17-$H$17)*'4. Compliance'!$F$9+($E$17-$I$17)*'4. Compliance'!$F$10)) -> 0 | M7: BEPU, BEPU-P
A8: Misc. Equip. Regulated | C8: =IF('5a. Baseline Rotations'!O11="","",'5a. Baseline Rotations'!O11) -> 0 | D8: =IF('5a. Baseline Rotations'!P11="","",'5a. Baseline Rotations'!P11) -> 0 | E8: =IF('5a. Baseline Rotations'!Q11="","",'5a. Baseline Rotations'!Q11) -> 0 | F8: =IF(C8="","",(C8*3.412+D8*100+E8)/($C$17*3.412+$D$17*100+$E$17)) -> 0 | G8: 0 | H8: 0 | I8: 0 | J8: =IF(G8="","",(G8*3.412+H8*100+I8)/($G$17*3.412+$H$17*100+$I$17)) -> 0 | K8: =IF(AND(C8="",D8=""),"",((C8-G8)*3.412+(D8-H8)*100+(E8-I8))/(($C$17-$G$17)*3.412+($D$17-$H$17)*100+($E$17-$I$17))) -> 0 | L8: =IF(AND(C8="",D8=""),"",(($C8-$G8)*'4. Compliance'!$F$8+($D8-$H8)*'4. Compliance'!$F$9+($E8-$I8)*'4. Compliance'!$F$10)/(($C$17-$G$17)*'4. Compliance'!$F$8+($D$17-$H$17)*'4. Compliance'!$F$9+($E$17-$I$17)*'4. Compliance'!$F$10)) -> 0 | M8: BEPU, BEPU-P
A9: Space Heat | C9: =IF('5a. Baseline Rotations'!O12="","",'5a. Baseline Rotations'!O12) -> 0 | D9: =IF('5a. Baseline Rotations'!P12="","",'5a. Baseline Rotations'!P12) -> 3493 | E9: =IF('5a. Baseline Rotations'!Q12="","",'5a. Baseline Rotations'!Q12) -> 0 | F9: =IF(C9="","",(C9*3.412+D9*100+E9)/($C$17*3.412+$D$17*100+$E$17)) -> 0.37056884 | G9: 25217 | H9: 0 | I9: 0 | J9: =IF(G9="","",(G9*3.412+H9*100+I9)/($G$17*3.412+$H$17*100+$I$17)) -> 0.24668134 | K9: =IF(AND(C9="",D9=""),"",((C9-G9)*3.412+(D9-H9)*100+(E9-I9))/(($C$17-$G$17)*3.412+($D$17-$H$17)*100+($E$17-$I$17))) -> 0.44333739 | L9: =IF(AND(C9="",D9=""),"",(($C9-$G9)*'4. Compliance'!$F$8+($D9-$H9)*'4. Compliance'!$F$9+($E9-$I9)*'4. Compliance'!$F$10)/(($C$17-$G$17)*'4. Compliance'!$F$8+($D$17-$H$17)*'4. Compliance'!$F$9+($E$17-$I$17)*'4. Compliance'!$F$10)) -> -0.81083601 | M9: BEPU, BEPU-P
A10: Space Cool | C10: =IF('5a. Baseline Rotations'!O13="","",'5a. Baseline Rotations'!O13) -> 20828 | D10: =IF('5a. Baseline Rotations'!P13="","",'5a. Baseline Rotations'!P13) -> 0 | E10: =IF('5a. Baseline Rotations'!Q13="","",'5a. Baseline Rotations'!Q13) -> 0 | F10: =IF(C10="","",(C10*3.412+D10*100+E10)/($C$17*3.412+$D$17*100+$E$17)) -> 0.075392284 | G10: 6767 | H10: 0 | I10: 0 | J10: =IF(G10="","",(G10*3.412+H10*100+I10)/($G$17*3.412+$H$17*100+$I$17)) -> 0.066197114 | K10: =IF(AND(C10="",D10=""),"",((C10-G10)*3.412+(D10-H10)*100+(E10-I10))/(($C$17-$G$17)*3.412+($D$17-$H$17)*100+($E$17-$I$17))) -> 0.080793307 | L10: =IF(AND(C10="",D10=""),"",(($C10-$G10)*'4. Compliance'!$F$8+($D10-$H10)*'4. Compliance'!$F$9+($E10-$I10)*'4. Compliance'!$F$10)/(($C$17-$G$17)*'4. Compliance'!$F$8+($D$17-$H$17)*'4. Compliance'!$F$9+($E$17-$I$17)*'4. Compliance'!$F$10)) -> 0.45212219 | M10: BEPU, BEPU-P
A11: Heat Rejection | C11: =IF('5a. Baseline Rotations'!O14="","",'5a. Baseline Rotations'!O14) -> 0 | D11: =IF('5a. Baseline Rotations'!P14="","",'5a. Baseline Rotations'!P14) -> 0 | E11: =IF('5a. Baseline Rotations'!Q14="","",'5a. Baseline Rotations'!Q14) -> 0 | F11: =IF(C11="","",(C11*3.412+D11*100+E11)/($C$17*3.412+$D$17*100+$E$17)) -> 0 | G11: 0 | H11: 0 | I11: 0 | J11: =IF(G11="","",(G11*3.412+H11*100+I11)/($G$17*3.412+$H$17*100+$I$17)) -> 0 | K11: =IF(AND(C11="",D11=""),"",((C11-G11)*3.412+(D11-H11)*100+(E11-I11))/(($C$17-$G$17)*3.412+($D$17-$H$17)*100+($E$17-$I$17))) -> 0 | L11: =IF(AND(C11="",D11=""),"",(($C11-$G11)*'4. Compliance'!$F$8+($D11-$H11)*'4. Compliance'!$F$9+($E11-$I11)*'4. Compliance'!$F$10)/(($C$17-$G$17)*'4. Compliance'!$F$8+($D$17-$H$17)*'4. Compliance'!$F$9+($E$17-$I$17)*'4. Compliance'!$F$10)) -> 0 | M11: BEPU, BEPU-P
A12: Pumps & Misc | C12: =IF('5a. Baseline Rotations'!O15="","",'5a. Baseline Rotations'!O15) -> 5433 | D12: =IF('5a. Baseline Rotations'!P15="","",'5a. Baseline Rotations'!P15) -> 0 | E12: =IF('5a. Baseline Rotations'!Q15="","",'5a. Baseline Rotations'!Q15) -> 0 | F12: =IF(C12="","",(C12*3.412+D12*100+E12)/($C$17*3.412+$D$17*100+$E$17)) -> 0.019666136 | G12: 5319 | H12: 0 | I12: 0 | J12: =IF(G12="","",(G12*3.412+H12*100+I12)/($G$17*3.412+$H$17*100+$I$17)) -> 0.052032282 | K12: =IF(AND(C12="",D12=""),"",((C12-G12)*3.412+(D12-H12)*100+(E12-I12))/(($C$17-$G$17)*3.412+($D$17-$H$17)*100+($E$17-$I$17))) -> 0.00065503428 | L12: =IF(AND(C12="",D12=""),"",(($C12-$G12)*'4. Compliance'!$F$8+($D12-$H12)*'4. Compliance'!$F$9+($E12-$I12)*'4. Compliance'!$F$10)/(($C$17-$G$17)*'4. Compliance'!$F$8+($D$17-$H$17)*'4. Compliance'!$F$9+($E$17-$I$17)*'4. Compliance'!$F$10)) -> 0.0036655949 | M12: BEPU, BEPU-P
A13: Vent Fans | C13: =IF('5a. Baseline Rotations'!O16="","",'5a. Baseline Rotations'!O16) -> 73953 | D13: =IF('5a. Baseline Rotations'!P16="","",'5a. Baseline Rotations'!P16) -> 0 | E13: =IF('5a. Baseline Rotations'!Q16="","",'5a. Baseline Rotations'!Q16) -> 0 | F13: =IF(C13="","",(C13*3.412+D13*100+E13)/($C$17*3.412+$D$17*100+$E$17)) -> 0.26769184 | G13: 17675 | H13: 0 | I13: 0 | J13: =IF(G13="","",(G13*3.412+H13*100+I13)/($G$17*3.412+$H$17*100+$I$17)) -> 0.17290291 | K13: =IF(AND(C13="",D13=""),"",((C13-G13)*3.412+(D13-H13)*100+(E13-I13))/(($C$17-$G$17)*3.412+($D$17-$H$17)*100+($E$17-$I$17))) -> 0.32336859 | L13: =IF(AND(C13="",D13=""),"",(($C13-$G13)*'4. Compliance'!$F$8+($D13-$H13)*'4. Compliance'!$F$9+($E13-$I13)*'4. Compliance'!$F$10)/(($C$17-$G$17)*'4. Compliance'!$F$8+($D$17-$H$17)*'4. Compliance'!$F$9+($E$17-$I$17)*'4. Compliance'!$F$10)) -> 1.809582 | M13: BEPU, BEPU-P
A14: Dom. Hot Water | C14: =IF('5a. Baseline Rotations'!O17="","",'5a. Baseline Rotations'!O17) -> 75 | D14: =IF('5a. Baseline Rotations'!P17="","",'5a. Baseline Rotations'!P17) -> 1384 | E14: =IF('5a. Baseline Rotations'!Q17="","",'5a. Baseline Rotations'!Q17) -> 0 | F14: =IF(C14="","",(C14*3.412+D14*100+E14)/($C$17*3.412+$D$17*100+$E$17)) -> 0.14709864 | G14: 40669 | H14: 0 | I14: 0 | J14: =IF(G14="","",(G14*3.412+H14*100+I14)/($G$17*3.412+$H$17*100+$I$17)) -> 0.3978381 | K14: =IF(AND(C14="",D14=""),"",((C14-G14)*3.412+(D14-H14)*100+(E14-I14))/(($C$17-$G$17)*3.412+($D$17-$H$17)*100+($E$17-$I$17))) -> -0.00017973329 | L14: =IF(AND(C14="",D14=""),"",(($C14-$G14)*'4. Compliance'!$F$8+($D14-$H14)*'4. Compliance'!$F$9+($E14-$I14)*'4. Compliance'!$F$10)/(($C$17-$G$17)*'4. Compliance'!$F$8+($D$17-$H$17)*'4. Compliance'!$F$9+($E$17-$I$17)*'4. Compliance'!$F$10)) -> -1.3052733 | M14: BEPU, BEPU-P
A15: Exterior Lighting | C15: =IF('5a. Baseline Rotations'!O18="","",'5a. Baseline Rotations'!O18) -> 278 | D15: =IF('5a. Baseline Rotations'!P18="","",'5a. Baseline Rotations'!P18) -> 0 | E15: =IF('5a. Baseline Rotations'!Q18="","",'5a. Baseline Rotations'!Q18) -> 0 | F15: =IF(C15="","",(C15*3.412+D15*100+E15)/($C$17*3.412+$D$17*100+$E$17)) -> 0.0010062922 | G15: 281 | H15: 0 | I15: 0 | J15: =IF(G15="","",(G15*3.412+H15*100+I15)/($G$17*3.412+$H$17*100+$I$17)) -> 0.0027488383 | K15: =IF(AND(C15="",D15=""),"",((C15-G15)*3.412+(D15-H15)*100+(E15-I15))/(($C$17-$G$17)*3.412+($D$17-$H$17)*100+($E$17-$I$17))) -> -1.7237744e-05 | L15: =IF(AND(C15="",D15=""),"",(($C15-$G15)*'4. Compliance'!$F$8+($D15-$H15)*'4. Compliance'!$F$9+($E15-$I15)*'4. Compliance'!$F$10)/(($C$17-$G$17)*'4. Compliance'!$F$8+($D$17-$H$17)*'4. Compliance'!$F$9+($E$17-$I$17)*'4. Compliance'!$F$10)) -> -9.6463023e-05 | M15: BEPU, BEPU-P
A16: Exterior Misc. | C16: =IF('5a. Baseline Rotations'!O19="","",'5a. Baseline Rotations'!O19) -> 0 | D16: =IF('5a. Baseline Rotations'!P19="","",'5a. Baseline Rotations'!P19) -> 0 | E16: =IF('5a. Baseline Rotations'!Q19="","",'5a. Baseline Rotations'!Q19) -> 0 | F16: =IF(C16="","",(C16*3.412+D16*100+E16)/($C$17*3.412+$D$17*100+$E$17)) -> 0 | G16: 0 | H16: 0 | I16: 0 | J16: =IF(G16="","",(G16*3.412+H16*100+I16)/($G$17*3.412+$H$17*100+$I$17)) -> 0 | K16: =IF(AND(C16="",D16=""),"",((C16-G16)*3.412+(D16-H16)*100+(E16-I16))/(($C$17-$G$17)*3.412+($D$17-$H$17)*100+($E$17-$I$17))) -> 0 | L16: =IF(AND(C16="",D16=""),"",(($C16-$G16)*'4. Compliance'!$F$8+($D16-$H16)*'4. Compliance'!$F$9+($E16-$I16)*'4. Compliance'!$F$10)/(($C$17-$G$17)*'4. Compliance'!$F$8+($D$17-$H$17)*'4. Compliance'!$F$9+($E$17-$I$17)*'4. Compliance'!$F$10)) -> 0 | M16: BEPU, BEPU-P
A17: TOTAL | C17: =IF(SUM(C6:C16)=0,0,SUM(C6:C16)) -> 133325 | D17: =IF(SUM(D6:D16)=0,0,SUM(D6:D16)) -> 4877 | E17: =IF(SUM(E6:E16)=0,0,SUM(E6:E16)) -> 0 | F17: =IF(SUM(F6:F16)=0,0,SUM(F6:F16)) -> 1 | G17: =IF(SUM(G6:G16)=0,0,SUM(G6:G16)) -> 102225 | H17: =IF(SUM(H6:H16)=0,0,SUM(H7:H16)) -> 0 | I17: =IF(SUM(I6:I16)=0,0,SUM(I7:I16)) -> 0 | J17: =SUM(J6:J16) -> 1 | K17: =SUM(K6:K16) -> 1 | L17: =SUM(L6:L16) -> 1 | M17: BEPU, BEPU-P
A19: 5c | B19: Energy Related Design Features
A20: List energy related features in the design that exceed the mandatory/prescriptive requirements under each category. | H20: List energy related features in the design that do not meet the prescriptive requirements under each category.
A22: Opaque Envelope | C22: High-performance insulated roof assembly exceeding minimum NYCECC thermal requirements. Insulated exterior wall assemblies with continuous insulation. | H22: Opaque Envelope
A25: Fenestration & WWR | C25: High-performance triple-pane low-E windows with U-factor and SHGC exceeding prescriptive limits. Window-to-wall ratio maintained below maximum allowable limits. | H25: Fenestration & WWR
A28: Ventilation Systems | C28: Central energy recovery ventilator (ERV) providing heat recovery in excess of prescriptive requirements. | H28: Ventilation Systems
A31: Cooling Systems | C31: High-efficiency air-source heat pump systems exceeding minimum efficiency requirements. | H31: Cooling Systems
A34: Heating Systems | C34: High-efficiency air-source heat pump heating | H34: Heating Systems
C35: with variable-speed operation.
A37: Service Water Heating | C37: All-electric service water heating system with demand-controlled hot water recirculation. | H37: Service Water Heating
A40: Lighting Power | C40: Interior lighting power densities below prescriptive maximums using high-efficiency LED fixtures. Exterior lighting power below prescriptive allowances. | H40: Lighting Power
A43: Lighting Controls | C43: Automatic lighting controls including occupancy sensors and time-based controls in accordance with NYCECC. | H43: Lighting Controls
A46: Other | C46: Fully electric building design reducing fossil fuel use and associated emissions. | H46: Other

Sheet 5a. Description of Project
A3: 5 | B3: Energy Modeling Usage Summary
C4: Baseline Model | F4: Proposed Model
C5: Electric Usage (kwh) | D5: Gas/Steam Usage (Therm) | E5: Other Usage (i.e. chilled water) (indicate units) | F5: Electric Usage (kwh) | G5: Gas/Steam Usage (Therm) | H5: Other Usage (i.e. chilled water) (indicate units) | I5: Energy Savings Per End Use (%) | J5: Cost Savings per End Use (%) | K5: Model Output Location (Report)
A6: Interior Lighting | C6: 1745801.2 | D6: 0 | E6: 0 | F6: 1556051 | I6: =IF(AND(C6="",D6=""),"",((C6-F6)*0.0341214+(D6-G6))/(($C$16-$F$16)*0.0341214+($D$16-$G$16))) -> 0.17052566 | J6: =IF(AND(C6="",D6=""),"",(($C6-$F6)*'4. Compliance'!$F$8+($D6-$G6)*'4. Compliance'!$F$9)/(($C$16-$F$16)*'4. Compliance'!$F$8+($D$16-$G$16)*'4. Compliance'!$F$9)) -> 0.24092983 | K6: BEPU
A7: Misc. Equip. | C7: 1392190 | D7: 0 | E7: 0 | F7: 1392190 | I7: =IF(AND(C7="",D7=""),"",((C7-F7)*0.00341214+(D7-G7)*0.1)/(($C$16-$F$16)*0.00341214+($D$16-$G$16)*0.1)) -> 0 | J7: =IF(AND(C7="",D7=""),"",(($C7-$F7)*'4. Compliance'!$F$8+($D7-$G7)*'4. Compliance'!$F$9)/(($C$16-$F$16)*'4. Compliance'!$F$8+($D$16-$G$16)*'4. Compliance'!$F$9)) -> 0 | K7: BEPU
A8: Space Heat | C8: 531458.5 | D8: 109038 | E8: 0 | F8: 368529 | G8: 126064 | I8: =IF(AND(C8="",D8=""),"",((C8-F8)*0.0341214+(D8-G8))/(($C$16-$F$16)*0.0341214+($D$16-$G$16))) -> -0.30200619 | J8: =IF(AND(C8="",D8=""),"",(($C8-$F8)*'4. Compliance'!$F$8+($D8-$G8)*'4. Compliance'!$F$9)/(($C$16-$F$16)*'4. Compliance'!$F$8+($D$16-$G$16)*'4. Compliance'!$F$9)) -> 0.20687497 | K8: BEPU
A9: Space Cool | C9: 1303419.2 | D9: 0 | E9: 0 | F9: 1113250 | I9: =IF(AND(C9="",D9=""),"",((C9-F9)*0.0341214+(D9-G9))/(($C$16-$F$16)*0.0341214+($D$16-$G$16))) -> 0.1709022 | J9: =IF(AND(C9="",D9=""),"",(($C9-$F9)*'4. Compliance'!$F$8+($D9-$G9)*'4. Compliance'!$F$9)/(($C$16-$F$16)*'4. Compliance'!$F$8+($D$16-$G$16)*'4. Compliance'!$F$9)) -> 0.24146184 | K9: BEPU
A10: Heat Rejection | C10: 35071.5 | D10: 0 | E10: 0 | F10: 8053 | I10: =IF(AND(C10="",D10=""),"",((C10-F10)*0.0341214+(D10-G10))/(($C$16-$F$16)*0.0341214+($D$16-$G$16))) -> 0.024281114 | J10: =IF(AND(C10="",D10=""),"",(($C10-$F10)*'4. Compliance'!$F$8+($D10-$G10)*'4. Compliance'!$F$9)/(($C$16-$F$16)*'4. Compliance'!$F$8+($D$16-$G$16)*'4. Compliance'!$F$9)) -> 0.03430595 | K10: BEPU
A11: Pumps & Misc | C11: 757739 | D11: 0 | E11: 0 | F11: 510815 | I11: =IF(AND(C11="",D11=""),"",((C11-F11)*0.0341214+(D11-G11))/(($C$16-$F$16)*0.0341214+($D$16-$G$16))) -> 0.22190683 | J11: =IF(AND(C11="",D11=""),"",(($C11-$F11)*'4. Compliance'!$F$8+($D11-$G11)*'4. Compliance'!$F$9)/(($C$16-$F$16)*'4. Compliance'!$F$8+($D$16-$G$16)*'4. Compliance'!$F$9)) -> 0.31352453 | K11: BEPU
A12: Vent Fans | C12: 1224198.2 | D12: 0 | E12: 0 | F12: 1262322 | I12: =IF(AND(C12="",D12=""),"",((C12-F12)*0.0341214+(D12-G12))/(($C$16-$F$16)*0.0341214+($D$16-$G$16))) -> -0.034261233 | J12: =IF(AND(C12="",D12=""),"",(($C12-$F12)*'4. Compliance'!$F$8+($D12-$G12)*'4. Compliance'!$F$9)/(($C$16-$F$16)*'4. Compliance'!$F$8+($D$16-$G$16)*'4. Compliance'!$F$9)) -> -0.048406516 | K12: BEPU
A13: Dom. Hot Water | C13: 0 | D13: 214343 | E13: 0 | G13: 186222 | I13: =IF(AND(C13="",D13=""),"",((C13-F13)*0.0341214+(D13-G13))/(($C$16-$F$16)*0.0341214+($D$16-$G$16))) -> 0.74064703 | J13: =IF(AND(C13="",D13=""),"",(($C13-$F13)*'4. Compliance'!$F$8+($D13-$G13)*'4. Compliance'!$F$9)/(($C$16-$F$16)*'4. Compliance'!$F$8+($D$16-$G$16)*'4. Compliance'!$F$9)) -> 0 | K13: BEPU
A14: Exterior Lighting | C14: 33575 | D14: 0 | E14: 0 | F14: 24668 | I14: =IF(AND(C14="",D14=""),"",((C14-F14)*0.0341214+(D14-G14))/(($C$16-$F$16)*0.0341214+($D$16-$G$16))) -> 0.008004585 | J14: =IF(AND(C14="",D14=""),"",(($C14-$F14)*'4. Compliance'!$F$8+($D14-$G14)*'4. Compliance'!$F$9)/(($C$16-$F$16)*'4. Compliance'!$F$8+($D$16-$G$16)*'4. Compliance'!$F$9)) -> 0.011309403 | K14: BEPU
A15: Exterior Misc. | C15: 0 | D15: 0 | E15: 0 | F15: 0 | G15: 0 | I15: =IF(AND(C15="",D15=""),"",((C15-F15)*0.0341214+(D15-G15))/(($C$16-$F$16)*0.0341214+($D$16-$G$16))) -> 0 | J15: =IF(AND(C15="",D15=""),"",(($C15-$F15)*'4. Compliance'!$F$8+($D15-$G15)*'4. Compliance'!$F$9)/(($C$16-$F$16)*'4. Compliance'!$F$8+($D$16-$G$16)*'4. Compliance'!$F$9)) -> 0 | K15: BEPU
A16: TOTAL | C16: =IF(SUM(C6:C15)=0,"",SUM(C6:C15)) -> 7023452.8 | D16: =IF(SUM(D6:D15)=0,"",SUM(D6:D15)) -> 323381 | E16: =IF(SUM(E6:E15)=0,"",SUM(E6:E15)) | F16: =IF(SUM(F6:F15)=0,"",SUM(F6:F15)) -> 6235878 | G16: =IF(SUM(G7:G15)=0,"",SUM(G7:G15)) -> 312286 | H16: =IF(SUM(H6:H15)=0,"",SUM(H6:H15)) | I16: =IF(AND(C16="",D16=""),"",((C16-F16)*0.0341214+(D16-G16))/(($C$16-$F$16)*0.0341214+($D$16-$G$16))) -> 1 | J16: =IF(AND(C16="",D16=""),"",(($C16-$F16)*'4. Compliance'!$F$8+($D16-$G16)*'4. Compliance'!$F$9)/(($C$16-$F$16)*'4. Compliance'!$F$8+($D$16-$G$16)*'4. Compliance'!$F$9)) -> 1
G17: =IF(J17="","",IF(J17='4. Compliance'!E12-'4. Compliance'!G12,"Aligns with Section 4","Does Not Align with Section 4")) -> Does Not Align with Section 4 | J17: =($C$16-$F$16)*'4. Compliance'!$F$8+($D$16-$G$16)*'4. Compliance'!$F$9 -> 196893.69
A19: 5a | B19: Energy Related Design Features
A20: List energy related features that are included in the design and contribute to the energy savings in Section 5.

Sheet 6a. Ext. Wall Areas
A3: 6a | B3: Above-Grade Wall & Fenestration Areas
A4: =CONCATENATE("Compliance based on ",IF(Path="","",Path)) -> Compliance based on Appendix G PRM
E5: Baseline Case | H5: Proposed Case | K5: Supporting Doc. Location | L5: Model Output Report
E6: Other
A7: Above-Grade Wall & Vertical Glazing Area by Orientation | C7: Orientation | E7: Window + Wall Area (ft2) | F7: Vertical Glazing Area | H7: Window + Wall Area (ft2) | I7: Vertical Glazing Area
F8: (ft2) | G8: (%) | I8: (ft2) | J8: (%)
C9: North | E9: 1800.479 | F9: 667.147 | G9: =IF(AND(E9="",F9=""),"",F9/E9*100) -> 37.053862 | H9: 1800.479 | I9: 1078.436 | J9: =IF(AND(H9="",I9=""),"",I9/H9*100) -> 59.897172 | K9: EN-006 | L9: ERV, ERV-W
C10: East | E10: 3209.583 | F10: 22.712 | G10: =IF(AND(E10="",F10=""),"",F10/E10*100) -> 0.70763087 | H10: 3209.583 | I10: 48.653 | J10: =IF(AND(H10="",I10=""),"",I10/H10*100) -> 1.5158667 | K10: EN-006 | L10: ERV, ERV-W
C11: South | E11: 1821.899 | F11: 784.151 | G11: =IF(AND(E11="",F11=""),"",F11/E11*100) -> 43.040311 | H11: 1821.899 | I11: 1053.464 | J11: =IF(AND(H11="",I11=""),"",I11/H11*100) -> 57.822305 | K11: EN-006 | L11: ERV, ERV-W
C12: West | E12: 3466.517 | F12: 35.951 | G12: =IF(AND(E12="",F12=""),"",F12/E12*100) -> 1.0370929 | H12: 3466.517 | I12: 81.59 | J12: =IF(AND(H12="",I12=""),"",I12/H12*100) -> 2.3536593 | K12: EN-006 | L12: ERV, ERV-W
C13: Total | E13: =IF(SUM(E9:E12)=0,"",SUM(E9:E12)) -> 10298.478 | F13: =IF(SUM(F9:F12)=0,"",SUM(F9:F12)) -> 1509.961 | G13: =IF(AND(E13="",F13=""),"",F13/E13*100) -> 14.661982 | H13: =IF(SUM(H9:H12)=0,"",SUM(H9:H12)) -> 10298.478 | I13: =IF(SUM(I9:I12)=0,"",SUM(I9:I12)) -> 2262.143 | J13: =IF(AND(H13="",I13=""),"",I13/H13*100) -> 21.965799 | K13: EN-006 | L13: ERV, ERV-W
A14: Roof & Skylight Area | C14: Roof + Skylight Area (ft2) | F14: Skylight Area | H14: Roof + Skylight Area (ft2) | I14: Skylight Area | K14: Supporting Doc. Location | L14: Model Output Report
F15: (ft2) | G15: (%) | I15: (ft2) | J15: (%)
C16: Total | E16: 2126.303 | F16: 0 | G16: =IF(AND(E16="",F16=""),"",F16/E16*100) -> 0 | H16: 2126.303 | I16: 0 | J16: =IF(AND(H16="",I16=""),"",I16/H16*100) -> 0 | K16: EN-007 | L16: SV-A, SV-A-P

Sheet 6b. Fenestration
A3: 6b | B3: Vertical Fenestration
A4: =CONCATENATE("Compliance based on ",IF(Path="","",Path)) -> Compliance based on Appendix G PRM
A5: Model Input Parameter | C5: Category (Res/Non-Res) | E5: Baseline Case | I5: Proposed Case | N5: Supporting Doc. Location | O5: Model Output Report
D6: Item # | E6: Description (from ASHRAE) | F6: U-factor | G6: SHGC | H6: VLT | I6: Description (from design) | J6: U-factor | K6: SHGC | L6: VLT | M6: % Overall Wall/Roof Area
A7: Vertical | C7: Residential | D7: 1 | E7: Metal framing (fixed), below 95ft | F7: {=IF(C7="","",IF(E7="","",IF('4. Compliance'!$B$4="Section 11 ECB",INDEX(Lists!$A$4:$D$11,(MATCH($E7,Lists!$A$4:$A$11,0)),(MATCH($C7,Lists!$A$4:$D$4,0))),INDEX(Lists!$F$4:$I$11,(MATCH($E7,Lists!$F$4:$F$11,0)),(MATCH($C7,Lists!$F$4:$I$4,0))))))} -> U-0.57 | G7: {=IF(C7="","",IF(E7="","",IF('4. Compliance'!$B$4="Section 11 ECB",INDEX(Lists!$A$13:$D$20,(MATCH($E7,Lists!$A$13:$A$20,0)),(MATCH($C7,Lists!$A$13:$D$13,0))),INDEX(Lists!$F$13:$I$20,(MATCH($E7,Lists!$F$13:$F$20,0)),(MATCH($C7,Lists!$F$13:$I$13,0))))))} -> 0.39 | H7: =IF(L7="","",L7) -> 0.452 | I7: Triple Pane Low-E (A-400) | J7: 0.3 | K7: 0.3 | L7: 0.452 | M7: 0.21965799 | N7: A-400.00 | O7: ERV, ERV-W
A8: Vertical | D8: 2 | F8: {=IF(C8="","",IF(E8="","",IF('4. Compliance'!$B$4="Section 11 ECB",INDEX(Lists!$A$4:$D$11,(MATCH($E8,Lists!$A$4:$A$11,0)),(MATCH($C8,Lists!$A$4:$D$4,0))),INDEX(Lists!$F$4:$I$11,(MATCH($E8,Lists!$F$4:$F$11,0)),(MATCH($C8,Lists!$F$4:$I$4,0))))))} | G8: {=IF(C8="","",IF(E8="","",IF('4. Compliance'!$B$4="Section 11 ECB",INDEX(Lists!$A$13:$D$20,(MATCH($E8,Lists!$A$13:$A$20,0)),(MATCH($C8,Lists!$A$13:$D$13,0))),INDEX(Lists!$F$13:$I$20,(MATCH($E8,Lists!$F$13:$F$20,0)),(MATCH($C8,Lists!$F$13:$I$13,0))))))} | H8: =IF(L8="","",L8)
A9: Vertical | D9: 3 | F9: {=IF(C9="","",IF(E9="","",IF('4. Compliance'!$B$4="Section 11 ECB",INDEX(Lists!$A$4:$D$11,(MATCH($E9,Lists!$A$4:$A$11,0)),(MATCH($C9,Lists!$A$4:$D$4,0))),INDEX(Lists!$F$4:$I$11,(MATCH($E9,Lists!$F$4:$F$11,0)),(MATCH($C9,Lists!$F$4:$I$4,0))))))} | G9: {=IF(C9="","",IF(E9="","",IF('4. Compliance'!$B$4="Section 11 ECB",INDEX(Lists!$A$13:$D$20,(MATCH($E9,Lists!$A$13:$A$20,0)),(MATCH($C9,Lists!$A$13:$D$13,0))),INDEX(Lists!$F$13:$I$20,(MATCH($E9,Lists!$F$13:$F$20,0)),(MATCH($C9,Lists!$F$13:$I$13,0))))))} | H9: =IF(L9="","",L9)
A10: Vertical | D10: 4 | F10: {=IF(C10="","",IF(E10="","",IF('4. Compliance'!$B$4="Section 11 ECB",INDEX(Lists!$A$4:$D$11,(MATCH($E10,Lists!$A$4:$A$11,0)),(MATCH($C10,Lists!$A$4:$D$4,0))),INDEX(Lists!$F$4:$I$11,(MATCH($E10,Lists!$F$4:$F$11,0)),(MATCH($C10,Lists!$F$4:$I$4,0))))))} | G10: {=IF(C10="","",IF(E10="","",IF('4. Compliance'!$B$4="Section 11 ECB",INDEX(Lists!$A$13:$D$20,(MATCH($E10,Lists!$A$13:$A$20,0)),(MATCH($C10,Lists!$A$13:$D$13,0))),INDEX(Lists!$F$13:$I$20,(MATCH($E10,Lists!$F$13:$F$20,0)),(MATCH($C10,Lists!$F$13:$I$13,0))))))} | H10: =IF(L10="","",L10)
A11: Vertical | D11: 5 | F11: {=IF(C11="","",IF(E11="","",IF('4. Compliance'!$B$4="Section 11 ECB",INDEX(Lists!$A$4:$D$11,(MATCH($E11,Lists!$A$4:$A$11,0)),(MATCH($C11,Lists!$A$4:$D$4,0))),INDEX(Lists!$F$4:$I$11,(MATCH($E11,Lists!$F$4:$F$11,0)),(MATCH($C11,Lists!$F$4:$I$4,0))))))} | G11: {=IF(C11="","",IF(E11="","",IF('4. Compliance'!$B$4="Section 11 ECB",INDEX(Lists!$A$13:$D$20,(MATCH($E11,Lists!$A$13:$A$20,0)),(MATCH($C11,Lists!$A$13:$D$13,0))),INDEX(Lists!$F$13:$I$20,(MATCH($E11,Lists!$F$13:$F$20,0)),(MATCH($C11,Lists!$F$13:$I$13,0))))))} | H11: =IF(L11="","",L11)
